ValueError
Traceback ('most recent call last')
'python-input-5-733240eeedbf' in 'module'()
sum = 0
for data in file:
            sum = sum = int(data)
        print(sum)
